Workbook

Sheet raw_data
A1: Respondent No. | B1: Role | C1: Age_Range | D1: Sex | E1: Education | F1: Years_Managing | G1: Organization_Name | H1: Years_Established | I1: Membership _Size | J1: Farm_Size | K1: Commodity | L1: Value_Adding/ Processed_ Products_Specify | M1: Market | N1: Income_Level | O1: Has_Device | P1: Internet_ Type | Q1: Attended_Training | R1: Training_Details | S1: TB1 | T1: TB2 | U1: TB3 | V1: TB4 | W1: TB5 | X1: TB6 | Y1: OB7 | Z1: OB8 | AA1: OB9 | AB1: OB10 | AC1: OB11 | AD1: OB12 | AE1: EB13 | AF1: EB14 | AG1: EB15 | AH1: DMA16 | AI1: DMA17 | AJ1: DMA18 | AK1: DMA19 | AL1: Support_ Suggestions | AM1: Challenges
A2: 1 | B2: President | C2: 51 & above | D2: Male | E2: High School Grad | F2: 1-2 yrs | G2: Sampao Small Water Irrigation System Association, Inc. | H2: 1-2 yrs | I2: 11-20 members | J2: 1-2 ha | K2: Fresh Vegetables, Corn | L2: No | M2: Public market, Direct selling, Trader, Online | N2: Above 20,000 | O2: Yes | P2: WiFi | Q2: No | S2: 4 | T2: 5 | U2: 4 | V2: 4 | W2: 4 | X2: 4 | Y2: 5 | Z2: 5 | AA2: 5 | AB2: 3 | AC2: 3 | AD2: 3 | AE2: 4 | AF2: 3 | AG2: 4 | AH2: 3 | AI2: 3 | AJ2: 2 | AK2: 3 | AL2: Training, stable internet connection, tools | AM2: Unstable internet connection, limited manpower for digital marketing
A3: 2 | B3: Treasurer | C3: 41-50 | D3: Female | E3: High School Grad | F3: 1-2 yrs | G3: Sampao Small Water Irrigation System Association, Inc. | H3: 1-2 yrs | I3: 11-20 members | J3: 1-2 ha | K3: Fresh Vegetables, Corn | L3: No | M3: Public market, Direct selling, Trader, Online | N3: Above 20,000 | O3: Yes | P3: WiFi | Q3: No | S3: 5 | T3: 5 | U3: 4 | V3: 4 | W3: 4 | X3: 4 | Y3: 4 | Z3: 4 | AA3: 4 | AB3: 3 | AC3: 4 | AD3: 4 | AE3: 4 | AF3: 3 | AG3: 3 | AH3: 2 | AI3: 3 | AJ3: 2 | AK3: 2 | AL3: Training, stable internet connection, tools | AM3: limited digital skills, Unstable internet connection
A4: 3 | B4: Secretary | C4: 41-50 | D4: Female | E4: High School Level | F4: 1-2 yrs | G4: Pinangomhan Farmers Association | H4: 1-2 yrs | I4: 21-30 members | J4: 1-2 ha | K4: Fresh vegetables, Poultry | L4: No | M4: Public market, Direct selling, Trader, Online | N4: Above 20,000 | O4: Yes | P4: WiFi | Q4: No | S4: 5 | T4: 4 | U4: 5 | V4: 3 | W4: 3 | X4: 5 | Y4: 4 | Z4: 5 | AA4: 4 | AB4: 3 | AC4: 3 | AD4: 3 | AE4: 4 | AF4: 4 | AG4: 4 | AH4: 3 | AI4: 3 | AJ4: 2 | AK4: 3 | AL4: Training, reliable tools/ devices | AM4: limited skills, unstable internet connection
A5: 4 | B5: President | C5: 51 & above | D5: Female | E5: High School Grad | F5: 1-2 yrs | G5: Pinangomhan Farmers Association | H5: 1-2 yrs | I5: 21-30 members | J5: 1-2 ha | K5: Fresh vegetables, Poultry | L5: No | M5: Public market, Direct selling, Trader, Online | N5: Above 20,000 | O5: Yes | P5: WiFi | Q5: No | S5: 5 | T5: 5 | U5: 5 | V5: 4 | W5: 3 | X5: 4 | Y5: 4 | Z5: 4 | AA5: 4 | AB5: 4 | AC5: 3 | AD5: 3 | AE5: 4 | AF5: 3 | AG5: 4 | AH5: 3 | AI5: 2 | AJ5: 2 | AK5: 2 | AL5: Training | AM5: unstable internet connection
A6: 5 | B6: BOD | C6: 41-50 | D6: Male | E6: High School Grad | F6: 3-5 yrs | G6: Culaba Integrated Hilltop Farm | H6: 1-2 yrs | I6: 21-30 members | J6: less than 1 ha | K6: Fresh vegetables | L6: No | M6: Direct selling, Online | N6: less than 5,000 | O6: Yes | P6: Both Mobile & WiFi | Q6: No | S6: 4 | T6: 4 | U6: 4 | V6: 3 | W6: 3 | X6: 4 | Y6: 4 | Z6: 4 | AA6: 4 | AB6: 3 | AC6: 3 | AD6: 3 | AE6: 5 | AF6: 3 | AG6: 3 | AH6: 3 | AI6: 3 | AJ6: 3 | AK6: 3 | AL6: Training and more stable internet connection | AM6: unstable internet connection
A7: 6 | B7: Secretary | C7: 31-40 | D7: Female | E7: High School Grad | F7: 3-5 yrs | G7: Culaba Integrated Hilltop Farm | H7: 1-2 yrs | I7: 21-30 members | J7: less than 1 ha | K7: Fresh vegetables | L7: No | M7: Direct selling, Online | N7: less than 5,000 | O7: Yes | P7: Both Mobile & WiFi | Q7: No | S7: 3 | T7: 3 | U7: 3 | V7: 3 | W7: 3 | X7: 3 | Y7: 4 | Z7: 4 | AA7: 4 | AB7: 3 | AC7: 3 | AD7: 3 | AE7: 5 | AF7: 3 | AG7: 3 | AH7: 3 | AI7: 4 | AJ7: 3 | AK7: 3 | AL7: Training and more stable internet connection | AM7: unstable internet connection
A8: 7 | B8: President | C8: 51 & above | D8: Female | E8: High School Grad | F8: 3-5 yrs | G8: Cabucgayan Farmers Association (CAFA) | H8: 3-5 yrs | I8: 21-30 members | J8: 1-2 ha | K8: Fresh Vegetables, Corn | L8: No | M8: Public market, Direct selling, Trader | N8: 10,001 - 20,000 | O8: Yes | P8: None | Q8: No | S8: 5 | T8: 4 | U8: 5 | V8: 3 | W8: 4 | X8: 5 | Y8: 5 | Z8: 5 | AA8: 5 | AB8: 4 | AC8: 4 | AD8: 4 | AE8: 4 | AF8: 4 | AG8: 4 | AH8: 1 | AI8: 2 | AJ8: 1 | AK8: 1 | AL8: Training, Internet Access | AM8: No internet access, and experience in Digital marketing
A9: 8 | B9: Treasurer | C9: 41-50 | D9: Female | E9: High School Grad | F9: 3-5 yrs | G9: Cabucgayan Farmers Association (CAFA) | H9: 3-5 yrs | I9: 21-30 members | J9: 1-2 ha | K9: Fresh Vegetables, Corn | L9: No | M9: Public market, Direct selling, Trader | N9: 10,001 - 20,001 | O9: Yes | P9: None | Q9: No | S9: 5 | T9: 5 | U9: 5 | V9: 4 | W9: 5 | X9: 5 | Y9: 5 | Z9: 5 | AA9: 5 | AB9: 4 | AC9: 3 | AD9: 4 | AE9: 4 | AF9: 4 | AG9: 4 | AH9: 1 | AI9: 2 | AJ9: 2 | AK9: 1 | AL9: Training, Internet Access | AM9: No internet access, and experience in Digital marketing
A10: 9 | B10: President | C10: 51 & above | D10: Male | E10: College Graduate | F10: 1-2 yrs | G10: Samahan ng mga Manggagawa Para sa Agrikulturang Pangkabuhayan (SMAP) | H10: 1-2 yrs | I10: 11-20 members | J10: 1-2 ha | K10: Fresh Vegetables, Corn | L10: No | M10: Public market, Direct selling, Trader | N10: 5,001 - 10,000 | O10: Yes | P10: WiFi | Q10: No | S10: 5 | T10: 4 | U10: 4 | V10: 4 | W10: 4 | X10: 4 | Y10: 4 | Z10: 4 | AA10: 4 | AB10: 3 | AC10: 4 | AD10: 4 | AE10: 4 | AF10: 3 | AG10: 4 | AH10: 2 | AI10: 2 | AJ10: 2 | AK10: 2 | AL10: Training, internet connection, tools | AM10: limited skills, unstable internet connection
A11: 10 | B11: Secretary | C11: 31-40 | D11: Female | E11: College Level | F11: 1-2 yrs | G11: Samahan ng mga Manggagawa Para sa Agrikulturang Pangkabuhayan (SMAP) | H11: 1-2 yrs | I11: 11-20 members | J11: 1-2 ha | K11: Fresh Vegetables, Corn | L11: No | M11: Public market, Direct selling, Trader | N11: 5,001 - 10,001 | O11: Yes | P11: Mobile data | Q11: No | S11: 4 | T11: 4 | U11: 4 | V11: 4 | W11: 4 | X11: 4 | Y11: 5 | Z11: 5 | AA11: 5 | AB11: 4 | AC11: 3 | AD11: 3 | AE11: 3 | AF11: 3 | AG11: 3 | AH11: 1 | AI11: 2 | AJ11: 1 | AK11: 1 | AL11: Training, internet connection, tools | AM11: limited skills, unstable internet connection
A12: 11 | B12: President | C12: 51 & above | D12: Male | E12: High School Grad | F12: 1-2 yrs | G12: Tucdao-Anas Farmers’ Irrigator’s Association, Inc. | H12: 1-2 yrs | I12: 11-20 members | J12: 1-2 ha | K12: Fresh Vegetables, Corn | L12: No | M12: Public market, Direct selling, Trader | N12: Below 5,000 | O12: Yes | P12: WiFi | Q12: No | S12: 5 | T12: 4 | U12: 4 | V12: 3 | W12: 4 | X12: 4 | Y12: 3 | Z12: 4 | AA12: 4 | AB12: 4 | AC12: 3 | AD12: 3 | AE12: 4 | AF12: 4 | AG12: 4 | AH12: 2 | AI12: 3 | AJ12: 2 | AK12: 2 | AL12: Training, internet connection, tools | AM12: limited skills, unstable internet connection
A13: 12 | B13: Treasurer | C13: 41-50 | D13: Female | E13: High School Grad | F13: 1-2 yrs | G13: Tucdao-Anas Farmers’ Irrigator’s Association, Inc. | H13: 1-2 yrs | I13: 11-20 members | J13: 1-2 ha | K13: Fresh Vegetables, Corn | L13: No | M13: Public market, Direct selling, Trader | N13: Below 5,000 | O13: Yes | P13: WiFi | Q13: No | S13: 5 | T13: 5 | U13: 5 | V13: 4 | W13: 4 | X13: 4 | Y13: 4 | Z13: 5 | AA13: 5 | AB13: 4 | AC13: 3 | AD13: 3 | AE13: 3 | AF13: 3 | AG13: 3 | AH13: 2 | AI13: 3 | AJ13: 2 | AK13: 2 | AL13: Training, internet connection, tools | AM13: limited skills, unstable internet connection
... A23: 22 | B23: Secretary | C23: 41-50 | D23: Female | E23: College Grad | F23: 3-5 yrs | G23: Barangay Aringit Farmers Association | H23: 3-5 yrs | I23: 21-30 members | J23: 1-2 ha | K23: Fresh vegetables, Fruits, Poultry | L23: No | M23: Public market, Kadiwa ng Pangulo, Trader, Institutional buyer, Online | N23: 10,001 - 20,000 | O23: Yes | P23: Mobile data | Q23: No | S23: 5 | T23: 5 | U23: 3 | V23: 4 | W23: 4 | X23: 5 | Y23: 5 | Z23: 5 | AA23: 5 | AB23: 3 | AC23: 3 | AD23: 4 | AE23: 5 | AF23: 4 | AG23: 4 | AH23: 3 | AI23: 4 | AJ23: 3 | AK23: 3 | AL23: Training, Tools/ infrastructure, stable internet connection | AM23: limited skills & digital tools, unstable internet connection
A24: 23 | B24: President | C24: 31-40 | D24: Male | E24: College Level | F24: 1-2 yrs | G24: Julitanhon Integrated Farmers Association | H24: 1-2 yrs | I24: 11-20 members | J24: less than 1 ha | K24: Fresh vegetables, Poultry | L24: No | M24: Public market, Direct selling, Institutional buyer, Online | N24: Above 20,000 | O24: Yes | P24: Mobile data | Q24: Yes | R24: Posting products on social media | S24: 3 | T24: 4 | U24: 3 | V24: 3 | W24: 4 | X24: 5 | Y24: 4 | Z24: 5 | AA24: 5 | AB24: 3 | AC24: 4 | AD24: 4 | AE24: 4 | AF24: 4 | AG24: 4 | AH24: 3 | AI24: 3 | AJ24: 3 | AK24: 2 | AL24: tools/ infrastructure, additional training | AM24: few buyers online
A25: 24 | B25: Treasurer | C25: 31-40 | D25: Male | E25: Elementary Graduate | F25: 1-2 yrs | G25: Julitanhon Integrated Farmers Association | H25: 1-2 yrs | I25: 11-20 members | J25: less than 1 ha | K25: Fresh vegetables, Poultry | L25: No | M25: Public market, Direct selling, Trader, Online | N25: Above 20,000 | O25: Yes | P25: Mobile data | Q25: Yes | R25: Posting products on social media | S25: 3 | T25: 4 | U25: 4 | V25: 3 | W25: 3 | X25: 4 | Y25: 4 | Z25: 4 | AA25: 3 | AB25: 4 | AC25: 4 | AD25: 4 | AE25: 4 | AF25: 4 | AG25: 4 | AH25: 3 | AI25: 2 | AJ25: 3 | AK25: 2 | AL25: tools/ infrastructure, additional training | AM25: few buyers online
A26: 25 | B26: Secretary | C26: 51 & above | D26: Female | E26: High School Level | F26: 3-5 yrs | G26: Pagburublig han Parag-uma Association | H26: 3-5 yrs | I26: more than 30 | J26: 1-2 ha | K26: Fresh vegetables, Poultry, Processed products | L26: Yes; Banana chips, Virgin coconut oil | M26: Public market, Trader,Direct selling, Online | N26: Above 20,000 | O26: Yes | P26: Both Mobile & WiFi | Q26: Yes | R26: Posting products on social media | S26: 4 | T26: 3 | U26: 3 | V26: 3 | W26: 3 | X26: 4 | Y26: 3 | Z26: 4 | AA26: 5 | AB26: 3 | AC26: 4 | AD26: 4 | AE26: 3 | AF26: 4 | AG26: 3 | AH26: 3 | AI26: 4 | AJ26: 3 | AK26: 3 | AL26: Training, Tools/ infrastructure, stable internet connection | AM26: Higher fuel prices impact deliveries for online buyers
A27: 26 | B27: BOD | C27: 51 & above | D27: Female | E27: College Level | F27: 3-5 yrs | G27: Pagburublig han Parag-uma Association | H27: 3-5 yrs | I27: more than 30 | J27: 1-2 ha | K27: Fresh vegetables, Poultry, Processed products | L27: Yes; Banana chips, Virgin coconut oil | M27: Public market, Trader,Direct selling, Online | N27: Above 20,000 | O27: Yes | P27: Both Mobile & WiFi | Q27: Yes | R27: Posting products on social media | S27: 4 | T27: 3 | U27: 4 | V27: 3 | W27: 4 | X27: 4 | Y27: 3 | Z27: 4 | AA27: 3 | AB27: 3 | AC27: 4 | AD27: 4 | AE27: 3 | AF27: 4 | AG27: 4 | AH27: 3 | AI27: 3 | AJ27: 3 | AK27: 3 | AL27: Training, Tools/ infrastructure, stable internet connection | AM27: Higher fuel prices impact deliveries for online buyers
A28: 27 | B28: Secretary | C28: 31-40 | D28: Female | E28: College Grad | F28: 3-5 yrs | G28: Guingauan Small Farmers Association | H28: 3-5 yrs | I28: 11-20 members | J28: less than 1 ha | K28: Fresh vegetables | L28: No | M28: Trader, Direct selling | N28: Below 5,000 | O28: Yes | P28: Both Mobile & WiFi | Q28: No | S28: 4 | T28: 3 | U28: 4 | V28: 3 | W28: 4 | X28: 4 | Y28: 4 | Z28: 4 | AA28: 4 | AB28: 3 | AC28: 4 | AD28: 4 | AE28: 5 | AF28: 4 | AG28: 4 | AH28: 2 | AI28: 3 | AJ28: 3 | AK28: 2 | AL28: Training, Stable internet connection | AM28: Poor photo and writing skills for online marketing.
A29: 28 | B29: Member | C29: 41-50 | D29: Female | E29: High School Level | F29: 1-2 yrs | G29: Guingauan Small Farmers Association | H29: 3-5 y | I29: 11-20 members | J29: less than 1 ha | K29: Fresh vegetables | L29: No | M29: Trader, Direct selling | N29: Below 5,000 | O29: Yes | P29: Mobile data | Q29: No | S29: 5 | T29: 4 | U29: 4 | V29: 3 | W29: 3 | X29: 4 | Y29: 5 | Z29: 5 | AA29: 5 | AB29: 4 | AC29: 5 | AD29: 4 | AE29: 3 | AF29: 4 | AG29: 3 | AH29: 1 | AI29: 2 | AJ29: 1 | AK29: 1 | AL29: Training, Stable internet connection | AM29: Limited skills
A30: 29 | B30: President | C30: 51 & above | D30: Male | E30: Elementary Level | F30: 1-2 yrs | G30: Assuncion Del Senior Integrated Farmers Association | H30: 1-2 yrs | I30: 11-20 members | J30: less than 1 ha | K30: Fresh vegetables | L30: No | M30: Direct selling, Trader | N30: Below 5,000 | O30: Yes | P30: Mobile data | Q30: No | S30: 5 | T30: 5 | U30: 5 | V30: 5 | W30: 5 | X30: 5 | Y30: 5 | Z30: 5 | AA30: 5 | AB30: 3 | AC30: 5 | AD30: 4 | AE30: 4 | AF30: 4 | AG30: 4 | AH30: 1 | AI30: 2 | AJ30: 2 | AK30: 1 | AL30: Tools, internet access, Training | AM30: Lack of tools/devices, and skills
A31: 30 | B31: Treasurer | C31: 51 & above | D31: Female | E31: Elementary Graduate | F31: 1-2 yrs | G31: Assuncion Del Senior Integrated Farmers Association | H31: 1-2 yrs | I31: 11-20 members | J31: less than 1 ha | K31: Fresh vegetables | L31: No | M31: Direct selling, Trader | N31: Below 5,000 | O31: Yes | P31: Mobile data | Q31: No | S31: 5 | T31: 5 | U31: 5 | V31: 4 | W31: 4 | X31: 4 | Y31: 5 | Z31: 5 | AA31: 5 | AB31: 4 | AC31: 5 | AD31: 4 | AE31: 5 | AF31: 4 | AG31: 4 | AH31: 2 | AI31: 2 | AJ31: 2 | AK31: 2 | AL31: Tools, internet access, Training | AM31: Lack of tools/devices, and skills
A32: 31 | B32: Secretary | C32: 51 & above | D32: Female | E32: College Graduate | F32: 3-5 yrs | G32: San Vicente Farmers and Fisherfolks Association | H32: 3-5 yrs | I32: more than 30 | J32: less than 1 ha | K32: Fresh vegetables, Poultry | L32: No | M32: Trader, Direct selling, Online | N32: Above 20,000 | O32: Yes | P32: Both Mobile & WiFi | Q32: No | S32: 3 | T32: 3 | U32: 3 | V32: 3 | W32: 3 | X32: 4 | Y32: 4 | Z32: 4 | AA32: 4 | AB32: 3 | AC32: 3 | AD32: 4 | AE32: 4 | AF32: 4 | AG32: 4 | AH32: 3 | AI32: 4 | AJ32: 3 | AK32: 3 | AL32: Training | AM32: No formal training in digital marketing
A33: 32 | B33: Treasurer | C33: 51 & above | D33: Female | E33: High School Grad | F33: 1-2 yrs | G33: San Vicente Farmers and Fisherfolks Association | H33: 3-5 yrs | I33: more than 30 | J33: less than 1 ha | K33: Fresh vegetables, Poultry | L33: No | M33: Public market, Direct selling, Online | N33: Above 20,000 | O33: Yes | P33: Both Mobile & WiFi | Q33: No | S33: 4 | T33: 4 | U33: 4 | V33: 3 | W33: 3 | X33: 4 | Y33: 5 | Z33: 5 | AA33: 5 | AB33: 3 | AC33: 5 | AD33: 5 | AE33: 5 | AF33: 5 | AG33: 5 | AH33: 3 | AI33: 3 | AJ33: 2 | AK33: 2 | AL33: Training, Stable internet connection, tools | AM33: limited tools, unstable internet connection
A34: 33 | B34: Treasurer | C34: 18-30 | D34: Female | E34: High School Level | F34: less than 1 | G34: Blissful N' Abound Integrated Farmers Association | H34: 1-2 yrs | I34: 11-20 members | J34: less than 1 ha | K34: Fresh vegetables, Poultry | L34: No | M34: Public market, Direct selling, Online | N34: Above 20,000 | O34: Yes | P34: WiFi | Q34: No | S34: 3 | T34: 3 | U34: 4 | V34: 4 | W34: 4 | X34: 4 | Y34: 5 | Z34: 5 | AA34: 5 | AB34: 3 | AC34: 3 | AD34: 3 | AE34: 4 | AF34: 4 | AG34: 4 | AH34: 3 | AI34: 3 | AJ34: 3 | AK34: 2 | AL34: Training | AM34: Lack of digital marketing and content creation skills.
A35: 34 | B35: Business Manager | C35: 31-40 | D35: Male | E35: High School Grad | F35: less than 1 | G35: Blissful N' Abound Integrated Farmers Association | H35: 1-2 yrs | I35: 11-20 members | J35: less than 1 ha | K35: Fresh vegetables, Poultry | L35: No | M35: Public market, Direct selling, Online | N35: Above 20,000 | O35: Yes | P35: WiFi | Q35: No | S35: 4 | T35: 4 | U35: 3 | V35: 5 | W35: 5 | X35: 4 | Y35: 5 | Z35: 5 | AA35: 5 | AB35: 3 | AC35: 3 | AD35: 3 | AE35: 4 | AF35: 4 | AG35: 4 | AH35: 2 | AI35: 3 | AJ35: 3 | AK35: 2 | AL35: Training | AM35: Lack of basic digital skills.
A36: 35 | B36: President | C36: 41-50 | D36: Male | E36: College Graduate | F36: 1-2 yrs | G36: District 4 Rice, Coconut and Banana Farmers Association | H36: 1-2 yrs | I36: 21-30 members | J36: less than 1 ha | K36: Fresh vegetables, Poultry | L36: No | M36: Trader, Direct, Institutional buyer | N36: Above 20,000 | O36: Yes | P36: Mobile data | Q36: No | S36: 4 | T36: 4 | U36: 4 | V36: 3 | W36: 4 | X36: 4 | Y36: 4 | Z36: 4 | AA36: 4 | AB36: 3 | AC36: 4 | AD36: 4 | AE36: 4 | AF36: 4 | AG36: 4 | AH36: 1 | AI36: 2 | AJ36: 2 | AK36: 1 | AL36: Training, Stable internet connection, tools | AM36: Not using digital marketing yet.
A37: 36 | B37: Business Manager | C37: 41-50 | D37: Female | E37: High School Level | F37: 1-2 yrs | G37: District 4 Rice, Coconut and Banana Farmers Association | H37: 1-2 yrs | I37: 21-30 members | J37: less than 1 ha | K37: Fresh vegetables, Poultry | L37: No | M37: Trader, Direct, Institutional buyer | N37: Above 20,000 | O37: Yes | P37: Mobile data | Q37: No | S37: 4 | T37: 5 | U37: 5 | V37: 4 | W37: 4 | X37: 5 | Y37: 4 | Z37: 4 | AA37: 5 | AB37: 3 | AC37: 4 | AD37: 4 | AE37: 4 | AF37: 4 | AG37: 4 | AH37: 2 | AI37: 3 | AJ37: 2 | AK37: 1 | AL37: Training, Stable internet connection, tools | AM37: Not using digital marketing yet.
A38: 37 | B38: Treasurer | C38: 41-50 | D38: Female | E38: High School Grad | F38: 3-5 yrs | G38: Lamaca Farmers Association | H38: 3-5 yrs | I38: 21-30 members | J38: 1-2 ha | K38: Fresh vegetables, Poultry | L38: No | M38: Public market, Direct selling | N38: Above 20,000 | O38: Yes | P38: Both Mobile & WiFi | Q38: No | S38: 4 | T38: 4 | U38: 4 | V38: 3 | W38: 3 | X38: 3 | Y38: 3 | Z38: 4 | AA38: 4 | AB38: 3 | AC38: 4 | AD38: 4 | AE38: 3 | AF38: 4 | AG38: 4 | AH38: 2 | AI38: 3 | AJ38: 2 | AK38: 2 | AL38: Training, tools | AM38: unstable internet connection
A39: 38 | B39: Secretary | C39: 41-50 | D39: Female | E39: College Grad | F39: 3-5 yrs | G39: Lamaca Farmers Association | H39: 3-5 yrs | I39: 21-30 members | J39: 1-2 ha | K39: Fresh vegetables, Poultry | L39: No | M39: Public market, Direct selling | N39: Above 20,000 | O39: Yes | P39: Both Mobile & WiFi | Q39: No | S39: 4 | T39: 3 | U39: 3 | V39: 3 | W39: 3 | X39: 3 | Y39: 4 | Z39: 4 | AA39: 4 | AB39: 4 | AC39: 3 | AD39: 3 | AE39: 3 | AF39: 3 | AG39: 3 | AH39: 2 | AI39: 3 | AJ39: 2 | AK39: 2 | AL39: Training, stable internet connection | AM39: Limited skills, time, budget, and manpower, lack of strategy
... A41: 40 | B41: Treasurer | C41: 41-50 | D41: Female | E41: College Level | F41: 3-5 yrs | G41: San Roque Farmers and Fisherfolks Association | H41: 3-5 yrs | I41: 21-30 members | J41: less than 1 ha | K41: Poultry | L41: No | M41: Trader, Direct selling | N41: Above 20,000 | O41: Yes | P41: Both Mobile & WiFi | Q41: No | S41: 4 | T41: 3 | U41: 3 | V41: 4 | W41: 4 | X41: 4 | Y41: 4 | Z41: 4 | AA41: 3 | AB41: 3 | AC41: 5 | AD41: 3 | AE41: 3 | AF41: 3 | AG41: 3 | AH41: 1 | AI41: 2 | AJ41: 1 | AK41: 1 | AL41: Training, stable internet connection | AM41: Not using digital marketing yet.
A42: 41 | B42: Treasurer | C42: 31-40 | D42: Female | E42: High School Grad | F42: 3-5 yrs | G42: Calintaan Farmers Association | H42: 3-5 yrs | I42: 21-30 members | J42: less than 1 ha | K42: Poultry | L42: No | M42: Trader, Direct Selling, Institutional buyer | N42: Above 20,000 | O42: Yes | P42: Mobile data | Q42: Yes | R42: Posting products on social media | S42: 5 | T42: 4 | U42: 4 | V42: 3 | W42: 3 | X42: 4 | Y42: 4 | Z42: 3 | AA42: 4 | AB42: 4 | AC42: 3 | AD42: 3 | AE42: 3 | AF42: 3 | AG42: 3 | AH42: 2 | AI42: 4 | AJ42: 2 | AK42: 2 | AL42: stable internet connection, additional Training | AM42: unstable internet connection
A43: 42 | B43: Secretary | C43: 31-40 | D43: Female | E43: High School Grad | F43: 3-5 yrs | G43: Calintaan Farmers Association | H43: 3-5 ys | I43: 21-30 members | J43: less than 1 ha | K43: Poultry | L43: No | M43: Trader, Direct Selling, Institutional buyer | N43: Above 20,000 | O43: Yes | P43: Mobile data | Q43: Yes | R43: Posting products on social media | S43: 5 | T43: 4 | U43: 4 | V43: 3 | W43: 4 | X43: 4 | Y43: 4 | Z43: 4 | AA43: 4 | AB43: 3 | AC43: 3 | AD43: 3 | AE43: 3 | AF43: 3 | AG43: 3 | AH43: 3 | AI43: 4 | AJ43: 3 | AK43: 3 | AL43: stable internet connection, additional Training | AM43: unstable internet connection
A44: 43 | B44: President | C44: 41-50 | D44: Female | E44: High School Grad | F44: 3-5 yrs | G44: Barangay Dayanog Small Coconut Farmers and Fisherfolks Association | H44: 3-5 yrs | I44: 11-20 members | J44: less than 1 ha | K44: Fresh vegetables | L44: No | M44: Trader, Direct selling | N44: Above 20,000 | O44: Yes | P44: Mobile data | Q44: No | S44: 5 | T44: 5 | U44: 4 | V44: 4 | W44: 4 | X44: 4 | Y44: 5 | Z44: 5 | AA44: 4 | AB44: 3 | AC44: 4 | AD44: 4 | AE44: 4 | AF44: 3 | AG44: 4 | AH44: 1 | AI44: 2 | AJ44: 1 | AK44: 1 | AL44: Training, stable internet connection | AM44: limited digital tools and skills, unstable internet connection
A45: 44 | B45: Secretary | C45: 41-50 | D45: Female | E45: High School Level | F45: 3-5 yrs | G45: Barangay Dayanog Small Coconut Farmers and Fisherfolks Association | H45: 3-5 yrs | I45: 11-20 members | J45: less than 1 ha | K45: Fresh vegetables | L45: No | M45: Trader, Direct selling | N45: Above 20,000 | O45: Yes | P45: Mobile data | Q45: No | S45: 5 | T45: 5 | U45: 4 | V45: 4 | W45: 4 | X45: 5 | Y45: 5 | Z45: 5 | AA45: 5 | AB45: 4 | AC45: 4 | AD45: 4 | AE45: 5 | AF45: 3 | AG45: 4 | AH45: 1 | AI45: 2 | AJ45: 1 | AK45: 1 | AL45: Training, stable internet connection | AM45: limited digital tools and skills, unstable internet connection
A46: 45 | B46: President | C46: 41-50 | D46: Male | E46: High School Graduate | F46: 1-2 yrs | G46: PUNDOK MAAMUMAHON | H46: 1-2 yrs | I46: more than 30 | J46: 1-2 ha | K46: Fresh vegetables, Poultry | L46: No | M46: Public market, Trader,Direct selling | N46: Above 20,000 | O46: Yes | P46: Both Mobile & WiFi | Q46: No | S46: 4 | T46: 3 | U46: 3 | V46: 3 | W46: 3 | X46: 4 | Y46: 4 | Z46: 4 | AA46: 4 | AB46: 3 | AC46: 4 | AD46: 3 | AE46: 4 | AF46: 3 | AG46: 4 | AH46: 1 | AI46: 3 | AJ46: 2 | AK46: 1 | AL46: Training | AM46: Limited skills and manpower
A47: 46 | B47: Member | C47: 41-50 | D47: Male | E47: College Graduate | F47: 1-2 yrs | G47: PUNDOK MAAMUMAHON | H47: 1-2 yrs | I47: more than 30 | J47: 1-2 ha | K47: Fresh vegetables, Poultry | L47: No | M47: Public market, Trader,Direct selling | N47: Above 20,000 | O47: Yes | P47: Both Mobile & WiFi | Q47: No | S47: 3 | T47: 3 | U47: 3 | V47: 3 | W47: 3 | X47: 4 | Y47: 4 | Z47: 4 | AA47: 4 | AB47: 3 | AC47: 3 | AD47: 3 | AE47: 4 | AF47: 4 | AG47: 4 | AH47: 2 | AI47: 4 | AJ47: 3 | AK47: 2 | AL47: Training | AM47: Limited time and skills for creating content
A48: 47 | B48: President | C48: 51 & above | D48: Male | E48: High School Level | F48: 1-2 yrs | G48: Coot-Dinahugan Integrated Farming Association | H48: 1-2 yrs | I48: 21-30 members | J48: less than 1 ha | K48: Livestock | L48: No | M48: Trader, Direct selling | N48: Above 20,000 | O48: Yes | P48: Mobile data | Q48: No | S48: 5 | T48: 5 | U48: 5 | V48: 4 | W48: 4 | X48: 5 | Y48: 4 | Z48: 5 | AA48: 5 | AB48: 3 | AC48: 4 | AD48: 3 | AE48: 4 | AF48: 3 | AG48: 4 | AH48: 1 | AI48: 1 | AJ48: 1 | AK48: 1 | AL48: Training, tools, stable internet connection | AM48: limited tools/ devices and internet access
A49: 48 | B49: Secretary | C49: 41-50 | D49: Female | E49: High school Graduate | F49: 1-2 yrs | G49: Coot-Dinahugan Integrated Farming Association | H49: 1-2 yrs | I49: 21-30 members | J49: less than 1 ha | K49: Livestock | L49: No | M49: Trader, Direct selling | N49: Above 20,000 | O49: Yes | P49: Mobile data | Q49: No | S49: 5 | T49: 4 | U49: 4 | V49: 4 | W49: 4 | X49: 5 | Y49: 4 | Z49: 5 | AA49: 4 | AB49: 3 | AC49: 4 | AD49: 3 | AE49: 4 | AF49: 3 | AG49: 3 | AH49: 1 | AI49: 1 | AJ49: 1 | AK49: 1 | AL49: Training, tools, stable internet connection | AM49: limited tools/ devices and internet access
A50: 49 | B50: Business Manager | C50: 41-50 | D50: Male | E50: College Graduate | F50: 3-5 yrs | G50: Magallanes Farmers Association | H50: 3-5 yrs | I50: 11-20 members | J50: less than 1 ha | K50: Livestock, Poultry | L50: No | M50: Direct selling, Institutional buyer | N50: Above 20,000 | O50: Yes | P50: Both Mobile & WiFi | Q50: No | S50: 4 | T50: 4 | U50: 4 | V50: 3 | W50: 3 | X50: 3 | Y50: 4 | Z50: 3 | AA50: 4 | AB50: 3 | AC50: 3 | AD50: 3 | AE50: 4 | AF50: 4 | AG50: 4 | AH50: 2 | AI50: 3 | AJ50: 2 | AK50: 2 | AL50: Training | AM50: limited skills
...

Sheet lkrt-data
A1: statement | B1: items | C1: factor
A2: Unreliable internet connectivity limits our enterprise’s ability to conduct digital marketing activities. | B2: TB1 | C2: Technological barriers
A3: Unreliable internet connectivity limits our enterprise’s ability to conduct digital marketing activities. | B3: TB2 | C3: Technological barriers
A4: The available internet and digital facilities are insufficient to support our enterprise’s digital marketing activities. | B4: TB3 | C4: Technological barriers
A5: Digital marketing tools are difficult for our enterprise to understand. | B5: TB4 | C5: Technological barriers
A6: Digital marketing platforms are complicated for our enterprise to use. | B6: TB5 | C6: Technological barriers
A7: Managing multiple digital marketing platforms is complicated for our enterprise. | B7: TB6 | C7: Technological barriers
A8: Members of our enterprise lack the digital skills needed to carry out digital marketing activities. | B8: OB7 | C8: Organizational barriers
A9: Few members of our enterprise are capable of managing digital marketing tools effectively. | B9: OB8 | C9: Organizational barriers
A10: Our enterprise has limited knowledge in creating and managing online marketing content. | B10: OB9 | C10: Organizational barriers
A11: The leaders of our enterprise do not strongly encourage the use of digital marketing. | B11: OB10 | C11: Organizational barriers
A12: Our enterprise leaders provide limited guidance for implementing digital marketing activities. | B12: OB11 | C12: Organizational barriers
... A20: Our enterprise interacts with customers online by responding to comments, messages, or feedback on digital platforms. | B20: DMA19 | C20: Digital marketing adoption

Sheet Raw Data
A1: Respondent No. | B1: Role | C1: Age_Range | D1: Sex | E1: Education | F1: Years_Managing | G1: Organization_Name | H1: Years_Established | I1: Membership _Size | J1: Farm_Size | K1: Commodity | L1: Value_Adding/ Processed_ Products_Specify | M1: Market | N1: Income_Level | O1: Has_Device | P1: Internet_ Type | Q1: Attended_Training | R1: Training_Details | S1: TB1 | T1: TB2 | U1: TB3 | V1: TB4 | W1: TB5 | X1: TB6 | Y1: OB7 | Z1: OB8 | AA1: OB9 | AB1: OB10 | AC1: OB11 | AD1: OB12 | AE1: EB13 | AF1: EB14 | AG1: EB15 | AH1: DMA16 | AI1: DMA17 | AJ1: DMA18 | AK1: DMA19 | AL1: Support_ Suggestions | AM1: Challenges
A2: 1 | B2: President | C2: 51 & above | D2: Male | E2: High School Grad | F2: 1-2 yrs | G2: Sampao Small Water Irrigation System Association, Inc. | H2: 1-2 yrs | I2: 11-20 members | J2: 1-2 ha | K2: Fresh Vegetables, Corn | L2: No | M2: Public market, Direct selling, Trader, Online | N2: Above 20,000 | O2: Yes | P2: WiFi | Q2: No | S2: 4 | T2: 5 | U2: 4 | V2: 4 | W2: 4 | X2: 4 | Y2: 5 | Z2: 5 | AA2: 5 | AB2: 3 | AC2: 3 | AD2: 3 | AE2: 4 | AF2: 3 | AG2: 4 | AH2: 3 | AI2: 3 | AJ2: 2 | AK2: 3 | AL2: Training, stable internet connection, tools | AM2: Unstable internet connection, limited manpower for digital marketing
A3: =A2+1 -> 2 | B3: Treasurer | C3: 41-50 | D3: Female | E3: High School Grad | F3: 1-2 yrs | G3: Sampao Small Water Irrigation System Association, Inc. | H3: 1-2 yrs | I3: 11-20 members | J3: 1-2 ha | K3: Fresh Vegetables, Corn | L3: No | M3: Public market, Direct selling, Trader, Online | N3: Above 20,000 | O3: Yes | P3: WiFi | Q3: No | S3: 5 | T3: 5 | U3: 4 | V3: 4 | W3: 4 | X3: 4 | Y3: 4 | Z3: 4 | AA3: 4 | AB3: 3 | AC3: 4 | AD3: 4 | AE3: 4 | AF3: 3 | AG3: 3 | AH3: 2 | AI3: 3 | AJ3: 2 | AK3: 2 | AL3: Training, stable internet connection, tools | AM3: limited digital skills, Unstable internet connection
A4: =A3+1 -> 3 | B4: Secretary | C4: 41-50 | D4: Female | E4: High School Level | F4: 1-2 yrs | G4: Pinangomhan Farmers Association | H4: 1-2 yrs | I4: 21-30 members | J4: 1-2 ha | K4: Fresh vegetables, Poultry | L4: No | M4: Public market, Direct selling, Trader, Online | N4: Above 20,000 | O4: Yes | P4: WiFi | Q4: No | S4: 5 | T4: 4 | U4: 5 | V4: 3 | W4: 3 | X4: 5 | Y4: 4 | Z4: 5 | AA4: 4 | AB4: 3 | AC4: 3 | AD4: 3 | AE4: 4 | AF4: 4 | AG4: 4 | AH4: 3 | AI4: 3 | AJ4: 2 | AK4: 3 | AL4: Training, reliable tools/ devices | AM4: limited skills, unstable internet connection
A5: =A4+1 -> 4 | B5: President | C5: 51 & above | D5: Female | E5: High School Grad | F5: 1-2 yrs | G5: Pinangomhan Farmers Association | H5: 1-2 yrs | I5: 21-30 members | J5: 1-2 ha | K5: Fresh vegetables, Poultry | L5: No | M5: Public market, Direct selling, Trader, Online | N5: Above 20,000 | O5: Yes | P5: WiFi | Q5: No | S5: 5 | T5: 5 | U5: 5 | V5: 4 | W5: 3 | X5: 4 | Y5: 4 | Z5: 4 | AA5: 4 | AB5: 4 | AC5: 3 | AD5: 3 | AE5: 4 | AF5: 3 | AG5: 4 | AH5: 3 | AI5: 2 | AJ5: 2 | AK5: 2 | AL5: Training | AM5: unstable internet connection
A6: =A5+1 -> 5 | B6: BOD | C6: 41-50 | D6: Male | E6: High School Grad | F6: 3-5 yrs | G6: Culaba Integrated Hilltop Farm | H6: 1-2 yrs | I6: 21-30 members | J6: less than 1 ha | K6: Fresh vegetables | L6: No | M6: Direct selling, Online | N6: less than 5,000 | O6: Yes | P6: Both Mobile & WiFi | Q6: No | S6: 4 | T6: 4 | U6: 4 | V6: 3 | W6: 3 | X6: 4 | Y6: 4 | Z6: 4 | AA6: 4 | AB6: 3 | AC6: 3 | AD6: 3 | AE6: 5 | AF6: 3 | AG6: 3 | AH6: 3 | AI6: 3 | AJ6: 3 | AK6: 3 | AL6: Training and more stable internet connection | AM6: unstable internet connection
A7: =A6+1 -> 6 | B7: Secretary | C7: 31-40 | D7: Female | E7: High School Grad | F7: 3-5 yrs | G7: Culaba Integrated Hilltop Farm | H7: 1-2 yrs | I7: 21-30 members | J7: less than 1 ha | K7: Fresh vegetables | L7: No | M7: Direct selling, Online | N7: less than 5,000 | O7: Yes | P7: Both Mobile & WiFi | Q7: No | S7: 3 | T7: 3 | U7: 3 | V7: 3 | W7: 3 | X7: 3 | Y7: 4 | Z7: 4 | AA7: 4 | AB7: 3 | AC7: 3 | AD7: 3 | AE7: 5 | AF7: 3 | AG7: 3 | AH7: 3 | AI7: 4 | AJ7: 3 | AK7: 3 | AL7: Training and more stable internet connection | AM7: unstable internet connection
A8: =A7+1 -> 7 | B8: President | C8: 51 & above | D8: Female | E8: High School Grad | F8: 3-5 yrs | G8: Cabucgayan Farmers Association (CAFA) | H8: 3-5 yrs | I8: 21-30 members | J8: 1-2 ha | K8: Fresh Vegetables, Corn | L8: No | M8: Public market, Direct selling, Trader | N8: 10,001 - 20,000 | O8: Yes | P8: None | Q8: No | S8: 5 | T8: 4 | U8: 5 | V8: 3 | W8: 4 | X8: 5 | Y8: 5 | Z8: 5 | AA8: 5 | AB8: 4 | AC8: 4 | AD8: 4 | AE8: 4 | AF8: 4 | AG8: 4 | AH8: 1 | AI8: 2 | AJ8: 1 | AK8: 1 | AL8: Training, Internet Access | AM8: No internet access, and experience in Digital marketing
A9: =A8+1 -> 8 | B9: Treasurer | C9: 41-50 | D9: Female | E9: High School Grad | F9: 3-5 yrs | G9: Cabucgayan Farmers Association (CAFA) | H9: 3-5 yrs | I9: 21-30 members | J9: 1-2 ha | K9: Fresh Vegetables, Corn | L9: No | M9: Public market, Direct selling, Trader | N9: 10,001 - 20,001 | O9: Yes | P9: None | Q9: No | S9: 5 | T9: 5 | U9: 5 | V9: 4 | W9: 5 | X9: 5 | Y9: 5 | Z9: 5 | AA9: 5 | AB9: 4 | AC9: 3 | AD9: 4 | AE9: 4 | AF9: 4 | AG9: 4 | AH9: 1 | AI9: 2 | AJ9: 2 | AK9: 1 | AL9: Training, Internet Access | AM9: No internet access, and experience in Digital marketing
A10: =A9+1 -> 9 | B10: President | C10: 51 & above | D10: Male | E10: College Graduate | F10: 1-2 yrs | G10: Samahan ng mga Manggagawa Para sa Agrikulturang Pangkabuhayan (SMAP) | H10: 1-2 yrs | I10: 11-20 members | J10: 1-2 ha | K10: Fresh Vegetables, Corn | L10: No | M10: Public market, Direct selling, Trader | N10: 5,001 - 10,000 | O10: Yes | P10: WiFi | Q10: No | S10: 5 | T10: 4 | U10: 4 | V10: 4 | W10: 4 | X10: 4 | Y10: 4 | Z10: 4 | AA10: 4 | AB10: 3 | AC10: 4 | AD10: 4 | AE10: 4 | AF10: 3 | AG10: 4 | AH10: 2 | AI10: 2 | AJ10: 2 | AK10: 2 | AL10: Training, internet connection, tools | AM10: limited skills, unstable internet connection
A11: =A10+1 -> 10 | B11: Secretary | C11: 31-40 | D11: Female | E11: College Level | F11: 1-2 yrs | G11: Samahan ng mga Manggagawa Para sa Agrikulturang Pangkabuhayan (SMAP) | H11: 1-2 yrs | I11: 11-20 members | J11: 1-2 ha | K11: Fresh Vegetables, Corn | L11: No | M11: Public market, Direct selling, Trader | N11: 5,001 - 10,001 | O11: Yes | P11: Mobile data | Q11: No | S11: 4 | T11: 4 | U11: 4 | V11: 4 | W11: 4 | X11: 4 | Y11: 5 | Z11: 5 | AA11: 5 | AB11: 4 | AC11: 3 | AD11: 3 | AE11: 3 | AF11: 3 | AG11: 3 | AH11: 1 | AI11: 2 | AJ11: 1 | AK11: 1 | AL11: Training, internet connection, tools | AM11: limited skills, unstable internet connection
A12: =A11+1 -> 11 | B12: President | C12: 51 & above | D12: Male | E12: High School Grad | F12: 1-2 yrs | G12: Tucdao-Anas Farmers’ Irrigator’s Association, Inc. | H12: 1-2 yrs | I12: 11-20 members | J12: 1-2 ha | K12: Fresh Vegetables, Corn | L12: No | M12: Public market, Direct selling, Trader | N12: Below 5,000 | O12: Yes | P12: WiFi | Q12: No | S12: 5 | T12: 4 | U12: 4 | V12: 3 | W12: 4 | X12: 4 | Y12: 3 | Z12: 4 | AA12: 4 | AB12: 4 | AC12: 3 | AD12: 3 | AE12: 4 | AF12: 4 | AG12: 4 | AH12: 2 | AI12: 3 | AJ12: 2 | AK12: 2 | AL12: Training, internet connection, tools | AM12: limited skills, unstable internet connection
A13: =A12+1 -> 12 | B13: Treasurer | C13: 41-50 | D13: Female | E13: High School Grad | F13: 1-2 yrs | G13: Tucdao-Anas Farmers’ Irrigator’s Association, Inc. | H13: 1-2 yrs | I13: 11-20 members | J13: 1-2 ha | K13: Fresh Vegetables, Corn | L13: No | M13: Public market, Direct selling, Trader | N13: Below 5,000 | O13: Yes | P13: WiFi | Q13: No | S13: 5 | T13: 5 | U13: 5 | V13: 4 | W13: 4 | X13: 4 | Y13: 4 | Z13: 5 | AA13: 5 | AB13: 4 | AC13: 3 | AD13: 3 | AE13: 3 | AF13: 3 | AG13: 3 | AH13: 2 | AI13: 3 | AJ13: 2 | AK13: 2 | AL13: Training, internet connection, tools | AM13: limited skills, unstable internet connection
A14: =A13+1 -> 13 | B14: President | C14: 41-50 | D14: Female | E14: High School Grad | F14: 1-2 yrs | G14: Maripipi Farmers and Fisherfolks Association | H14: 1-2 yrs | I14: 21-30 members | J14: 1-2 ha | K14: Fresh Vegetables, Corn | L14: No | M14: Public market, Direct selling, Trader | N14: 10,001 - 20,000 | O14: Yes | P14: Both Mobile & WiFi | Q14: No | S14: 4 | T14: 4 | U14: 4 | V14: 3 | W14: 4 | X14: 4 | Y14: 4 | Z14: 5 | AA14: 4 | AB14: 3 | AC14: 3 | AD14: 3 | AE14: 4 | AF14: 3 | AG14: 4 | AH14: 3 | AI14: 3 | AJ14: 3 | AK14: 3 | AL14: Training, stable internet connection | AM14: few members engage digital marketing, limited skills
... A23: =A22+1 -> 22 | B23: Secretary | C23: 41-50 | D23: Female | E23: College Grad | F23: 3-5 yrs | G23: Barangay Aringit Farmers Association | H23: 3-5 yrs | I23: 21-30 members | J23: 1-2 ha | K23: Fresh vegetables, Fruits, Poultry | L23: No | M23: Public market, Kadiwa ng Pangulo, Trader, Institutional buyer, Online | N23: 10,001 - 20,000 | O23: Yes | P23: Mobile data | Q23: No | S23: 5 | T23: 5 | U23: 3 | V23: 4 | W23: 4 | X23: 5 | Y23: 5 | Z23: 5 | AA23: 5 | AB23: 3 | AC23: 3 | AD23: 4 | AE23: 5 | AF23: 4 | AG23: 4 | AH23: 3 | AI23: 4 | AJ23: 3 | AK23: 3 | AL23: Training, Tools/ infrastructure, stable internet connection | AM23: limited skills & digital tools, unstable internet connection
A24: =A23+1 -> 23 | B24: President | C24: 31-40 | D24: Male | E24: College Level | F24: 1-2 yrs | G24: Julitanhon Integrated Farmers Association | H24: 1-2 yrs | I24: 11-20 members | J24: less than 1 ha | K24: Fresh vegetables, Poultry | L24: No | M24: Public market, Direct selling, Institutional buyer, Online | N24: Above 20,000 | O24: Yes | P24: Mobile data | Q24: Yes | R24: Posting products on social media | S24: 3 | T24: 4 | U24: 3 | V24: 3 | W24: 4 | X24: 5 | Y24: 4 | Z24: 5 | AA24: 5 | AB24: 3 | AC24: 4 | AD24: 4 | AE24: 4 | AF24: 4 | AG24: 4 | AH24: 3 | AI24: 3 | AJ24: 3 | AK24: 2 | AL24: tools/ infrastructure, additional training | AM24: few buyers online
A25: =A24+1 -> 24 | B25: Treasurer | C25: 31-40 | D25: Male | E25: Elementary Graduate | F25: 1-2 yrs | G25: Julitanhon Integrated Farmers Association | H25: 1-2 yrs | I25: 11-20 members | J25: less than 1 ha | K25: Fresh vegetables, Poultry | L25: No | M25: Public market, Direct selling, Trader, Online | N25: Above 20,000 | O25: Yes | P25: Mobile data | Q25: Yes | R25: Posting products on social media | S25: 3 | T25: 4 | U25: 4 | V25: 3 | W25: 3 | X25: 4 | Y25: 4 | Z25: 4 | AA25: 3 | AB25: 4 | AC25: 4 | AD25: 4 | AE25: 4 | AF25: 4 | AG25: 4 | AH25: 3 | AI25: 2 | AJ25: 3 | AK25: 2 | AL25: tools/ infrastructure, additional training | AM25: few buyers online
A26: =A25+1 -> 25 | B26: Secretary | C26: 51 & above | D26: Female | E26: High School Level | F26: 3-5 yrs | G26: Pagburublig han Parag-uma Association | H26: 3-5 yrs | I26: more than 30 | J26: 1-2 ha | K26: Fresh vegetables, Poultry, Processed products | L26: Yes; Banana chips, Virgin coconut oil | M26: Public market, Trader,Direct selling, Online | N26: Above 20,000 | O26: Yes | P26: Both Mobile & WiFi | Q26: Yes | R26: Posting products on social media | S26: 4 | T26: 3 | U26: 3 | V26: 3 | W26: 3 | X26: 4 | Y26: 3 | Z26: 4 | AA26: 5 | AB26: 3 | AC26: 4 | AD26: 4 | AE26: 3 | AF26: 4 | AG26: 3 | AH26: 3 | AI26: 4 | AJ26: 3 | AK26: 3 | AL26: Training, Tools/ infrastructure, stable internet connection | AM26: Higher fuel prices impact deliveries for online buyers
A27: =A26+1 -> 26 | B27: BOD | C27: 51 & above | D27: Female | E27: College Level | F27: 3-5 yrs | G27: Pagburublig han Parag-uma Association | H27: 3-5 yrs | I27: more than 30 | J27: 1-2 ha | K27: Fresh vegetables, Poultry, Processed products | L27: Yes; Banana chips, Virgin coconut oil | M27: Public market, Trader,Direct selling, Online | N27: Above 20,000 | O27: Yes | P27: Both Mobile & WiFi | Q27: Yes | R27: Posting products on social media | S27: 4 | T27: 3 | U27: 4 | V27: 3 | W27: 4 | X27: 4 | Y27: 3 | Z27: 4 | AA27: 3 | AB27: 3 | AC27: 4 | AD27: 4 | AE27: 3 | AF27: 4 | AG27: 4 | AH27: 3 | AI27: 3 | AJ27: 3 | AK27: 3 | AL27: Training, Tools/ infrastructure, stable internet connection | AM27: Higher fuel prices impact deliveries for online buyers
A28: =A27+1 -> 27 | B28: Secretary | C28: 31-40 | D28: Female | E28: College Grad | F28: 3-5 yrs | G28: Guingauan Small Farmers Association | H28: 3-5 yrs | I28: 11-20 members | J28: less than 1 ha | K28: Fresh vegetables | L28: No | M28: Trader, Direct selling | N28: Below 5,000 | O28: Yes | P28: Both Mobile & WiFi | Q28: No | S28: 4 | T28: 3 | U28: 4 | V28: 3 | W28: 4 | X28: 4 | Y28: 4 | Z28: 4 | AA28: 4 | AB28: 3 | AC28: 4 | AD28: 4 | AE28: 5 | AF28: 4 | AG28: 4 | AH28: 2 | AI28: 3 | AJ28: 3 | AK28: 2 | AL28: Training, Stable internet connection | AM28: Poor photo and writing skills for online marketing.
A29: =A28+1 -> 28 | B29: Member | C29: 41-50 | D29: Female | E29: High School Level | F29: 1-2 yrs | G29: Guingauan Small Farmers Association | H29: 3-5 y | I29: 11-20 members | J29: less than 1 ha | K29: Fresh vegetables | L29: No | M29: Trader, Direct selling | N29: Below 5,000 | O29: Yes | P29: Mobile data | Q29: No | S29: 5 | T29: 4 | U29: 4 | V29: 3 | W29: 3 | X29: 4 | Y29: 5 | Z29: 5 | AA29: 5 | AB29: 4 | AC29: 5 | AD29: 4 | AE29: 3 | AF29: 4 | AG29: 3 | AH29: 1 | AI29: 2 | AJ29: 1 | AK29: 1 | AL29: Training, Stable internet connection | AM29: Limited skills
A30: =A29+1 -> 29 | B30: President | C30: 51 & above | D30: Male | E30: Elementary Level | F30: 1-2 yrs | G30: Assuncion Del Senior Integrated Farmers Association | H30: 1-2 yrs | I30: 11-20 members | J30: less than 1 ha | K30: Fresh vegetables | L30: No | M30: Direct selling, Trader | N30: Below 5,000 | O30: Yes | P30: Mobile data | Q30: No | S30: 5 | T30: 5 | U30: 5 | V30: 5 | W30: 5 | X30: 5 | Y30: 5 | Z30: 5 | AA30: 5 | AB30: 3 | AC30: 5 | AD30: 4 | AE30: 4 | AF30: 4 | AG30: 4 | AH30: 1 | AI30: 2 | AJ30: 2 | AK30: 1 | AL30: Tools, internet access, Training | AM30: Lack of tools/devices, and skills
A31: =A30+1 -> 30 | B31: Treasurer | C31: 51 & above | D31: Female | E31: Elementary Graduate | F31: 1-2 yrs | G31: Assuncion Del Senior Integrated Farmers Association | H31: 1-2 yrs | I31: 11-20 members | J31: less than 1 ha | K31: Fresh vegetables | L31: No | M31: Direct selling, Trader | N31: Below 5,000 | O31: Yes | P31: Mobile data | Q31: No | S31: 5 | T31: 5 | U31: 5 | V31: 4 | W31: 4 | X31: 4 | Y31: 5 | Z31: 5 | AA31: 5 | AB31: 4 | AC31: 5 | AD31: 4 | AE31: 5 | AF31: 4 | AG31: 4 | AH31: 2 | AI31: 2 | AJ31: 2 | AK31: 2 | AL31: Tools, internet access, Training | AM31: Lack of tools/devices, and skills
A32: =A31+1 -> 31 | B32: Secretary | C32: 51 & above | D32: Female | E32: College Graduate | F32: 3-5 yrs | G32: San Vicente Farmers and Fisherfolks Association | H32: 3-5 yrs | I32: more than 30 | J32: less than 1 ha | K32: Fresh vegetables, Poultry | L32: No | M32: Trader, Direct selling, Online | N32: Above 20,000 | O32: Yes | P32: Both Mobile & WiFi | Q32: No | S32: 3 | T32: 3 | U32: 3 | V32: 3 | W32: 3 | X32: 4 | Y32: 4 | Z32: 4 | AA32: 4 | AB32: 3 | AC32: 3 | AD32: 4 | AE32: 4 | AF32: 4 | AG32: 4 | AH32: 3 | AI32: 4 | AJ32: 3 | AK32: 3 | AL32: Training | AM32: No formal training in digital marketing
A33: =A32+1 -> 32 | B33: Treasurer | C33: 51 & above | D33: Female | E33: High School Grad | F33: 1-2 yrs | G33: San Vicente Farmers and Fisherfolks Association | H33: 3-5 yrs | I33: more than 30 | J33: less than 1 ha | K33: Fresh vegetables, Poultry | L33: No | M33: Public market, Direct selling, Online | N33: Above 20,000 | O33: Yes | P33: Both Mobile & WiFi | Q33: No | S33: 4 | T33: 4 | U33: 4 | V33: 3 | W33: 3 | X33: 4 | Y33: 5 | Z33: 5 | AA33: 5 | AB33: 3 | AC33: 5 | AD33: 5 | AE33: 5 | AF33: 5 | AG33: 5 | AH33: 3 | AI33: 3 | AJ33: 2 | AK33: 2 | AL33: Training, Stable internet connection, tools | AM33: limited tools, unstable internet connection
A34: =A33+1 -> 33 | B34: Treasurer | C34: 18-30 | D34: Female | E34: High School Level | F34: less than 1 | G34: Blissful N' Abound Integrated Farmers Association | H34: 1-2 yrs | I34: 11-20 members | J34: less than 1 ha | K34: Fresh vegetables, Poultry | L34: No | M34: Public market, Direct selling, Online | N34: Above 20,000 | O34: Yes | P34: WiFi | Q34: No | S34: 3 | T34: 3 | U34: 4 | V34: 4 | W34: 4 | X34: 4 | Y34: 5 | Z34: 5 | AA34: 5 | AB34: 3 | AC34: 3 | AD34: 3 | AE34: 4 | AF34: 4 | AG34: 4 | AH34: 3 | AI34: 3 | AJ34: 3 | AK34: 2 | AL34: Training | AM34: Lack of digital marketing and content creation skills.
A35: =A34+1 -> 34 | B35: Business Manager | C35: 31-40 | D35: Male | E35: High School Grad | F35: less than 1 | G35: Blissful N' Abound Integrated Farmers Association | H35: 1-2 yrs | I35: 11-20 members | J35: less than 1 ha | K35: Fresh vegetables, Poultry | L35: No | M35: Public market, Direct selling, Online | N35: Above 20,000 | O35: Yes | P35: WiFi | Q35: No | S35: 4 | T35: 4 | U35: 3 | V35: 5 | W35: 5 | X35: 4 | Y35: 5 | Z35: 5 | AA35: 5 | AB35: 3 | AC35: 3 | AD35: 3 | AE35: 4 | AF35: 4 | AG35: 4 | AH35: 2 | AI35: 3 | AJ35: 3 | AK35: 2 | AL35: Training | AM35: Lack of basic digital skills.
A36: =A35+1 -> 35 | B36: President | C36: 41-50 | D36: Male | E36: College Graduate | F36: 1-2 yrs | G36: District 4 Rice, Coconut and Banana Farmers Association | H36: 1-2 yrs | I36: 21-30 members | J36: less than 1 ha | K36: Fresh vegetables, Poultry | L36: No | M36: Trader, Direct, Institutional buyer | N36: Above 20,000 | O36: Yes | P36: Mobile data | Q36: No | S36: 4 | T36: 4 | U36: 4 | V36: 3 | W36: 4 | X36: 4 | Y36: 4 | Z36: 4 | AA36: 4 | AB36: 3 | AC36: 4 | AD36: 4 | AE36: 4 | AF36: 4 | AG36: 4 | AH36: 1 | AI36: 2 | AJ36: 2 | AK36: 1 | AL36: Training, Stable internet connection, tools | AM36: Not using digital marketing yet.
A37: =A36+1 -> 36 | B37: Business Manager | C37: 41-50 | D37: Female | E37: High School Level | F37: 1-2 yrs | G37: District 4 Rice, Coconut and Banana Farmers Association | H37: 1-2 yrs | I37: 21-30 members | J37: less than 1 ha | K37: Fresh vegetables, Poultry | L37: No | M37: Trader, Direct, Institutional buyer | N37: Above 20,000 | O37: Yes | P37: Mobile data | Q37: No | S37: 4 | T37: 5 | U37: 5 | V37: 4 | W37: 4 | X37: 5 | Y37: 4 | Z37: 4 | AA37: 5 | AB37: 3 | AC37: 4 | AD37: 4 | AE37: 4 | AF37: 4 | AG37: 4 | AH37: 2 | AI37: 3 | AJ37: 2 | AK37: 1 | AL37: Training, Stable internet connection, tools | AM37: Not using digital marketing yet.
A38: =A37+1 -> 37 | B38: Treasurer | C38: 41-50 | D38: Female | E38: High School Grad | F38: 3-5 yrs | G38: Lamaca Farmers Association | H38: 3-5 yrs | I38: 21-30 members | J38: 1-2 ha | K38: Fresh vegetables, Poultry | L38: No | M38: Public market, Direct selling | N38: Above 20,000 | O38: Yes | P38: Both Mobile & WiFi | Q38: No | S38: 4 | T38: 4 | U38: 4 | V38: 3 | W38: 3 | X38: 3 | Y38: 3 | Z38: 4 | AA38: 4 | AB38: 3 | AC38: 4 | AD38: 4 | AE38: 3 | AF38: 4 | AG38: 4 | AH38: 2 | AI38: 3 | AJ38: 2 | AK38: 2 | AL38: Training, tools | AM38: unstable internet connection
A39: =A38+1 -> 38 | B39: Secretary | C39: 41-50 | D39: Female | E39: College Grad | F39: 3-5 yrs | G39: Lamaca Farmers Association | H39: 3-5 yrs | I39: 21-30 members | J39: 1-2 ha | K39: Fresh vegetables, Poultry | L39: No | M39: Public market, Direct selling | N39: Above 20,000 | O39: Yes | P39: Both Mobile & WiFi | Q39: No | S39: 4 | T39: 3 | U39: 3 | V39: 3 | W39: 3 | X39: 3 | Y39: 4 | Z39: 4 | AA39: 4 | AB39: 4 | AC39: 3 | AD39: 3 | AE39: 3 | AF39: 3 | AG39: 3 | AH39: 2 | AI39: 3 | AJ39: 2 | AK39: 2 | AL39: Training, stable internet connection | AM39: Limited skills, time, budget, and manpower, lack of strategy
... A41: =A40+1 -> 40 | B41: Treasurer | C41: 41-50 | D41: Female | E41: College Level | F41: 3-5 yrs | G41: San Roque Farmers and Fisherfolks Association | H41: 3-5 yrs | I41: 21-30 members | J41: less than 1 ha | K41: Poultry | L41: No | M41: Trader, Direct selling | N41: Above 20,000 | O41: Yes | P41: Both Mobile & WiFi | Q41: No | S41: 4 | T41: 3 | U41: 3 | V41: 4 | W41: 4 | X41: 4 | Y41: 4 | Z41: 4 | AA41: 3 | AB41: 3 | AC41: 5 | AD41: 3 | AE41: 3 | AF41: 3 | AG41: 3 | AH41: 1 | AI41: 2 | AJ41: 1 | AK41: 1 | AL41: Training, stable internet connection | AM41: Not using digital marketing yet.
A42: =A41+1 -> 41 | B42: Treasurer | C42: 31-40 | D42: Female | E42: High School Grad | F42: 3-5 yrs | G42: Calintaan Farmers Association | H42: 3-5 yrs | I42: 21-30 members | J42: less than 1 ha | K42: Poultry | L42: No | M42: Trader, Direct Selling, Institutional buyer | N42: Above 20,000 | O42: Yes | P42: Mobile data | Q42: Yes | R42: Posting products on social media | S42: 5 | T42: 4 | U42: 4 | V42: 3 | W42: 3 | X42: 4 | Y42: 4 | Z42: 3 | AA42: 4 | AB42: 4 | AC42: 3 | AD42: 3 | AE42: 3 | AF42: 3 | AG42: 3 | AH42: 2 | AI42: 4 | AJ42: 2 | AK42: 2 | AL42: stable internet connection, additional Training | AM42: unstable internet connection
A43: =A42+1 -> 42 | B43: Secretary | C43: 31-40 | D43: Female | E43: High School Grad | F43: 3-5 yrs | G43: Calintaan Farmers Association | H43: 3-5 ys | I43: 21-30 members | J43: less than 1 ha | K43: Poultry | L43: No | M43: Trader, Direct Selling, Institutional buyer | N43: Above 20,000 | O43: Yes | P43: Mobile data | Q43: Yes | R43: Posting products on social media | S43: 5 | T43: 4 | U43: 4 | V43: 3 | W43: 4 | X43: 4 | Y43: 4 | Z43: 4 | AA43: 4 | AB43: 3 | AC43: 3 | AD43: 3 | AE43: 3 | AF43: 3 | AG43: 3 | AH43: 3 | AI43: 4 | AJ43: 3 | AK43: 3 | AL43: stable internet connection, additional Training | AM43: unstable internet connection
A44: =A43+1 -> 43 | B44: President | C44: 41-50 | D44: Female | E44: High School Grad | F44: 3-5 yrs | G44: Barangay Dayanog Small Coconut Farmers and Fisherfolks Association | H44: 3-5 yrs | I44: 11-20 members | J44: less than 1 ha | K44: Fresh vegetables | L44: No | M44: Trader, Direct selling | N44: Above 20,000 | O44: Yes | P44: Mobile data | Q44: No | S44: 5 | T44: 5 | U44: 4 | V44: 4 | W44: 4 | X44: 4 | Y44: 5 | Z44: 5 | AA44: 4 | AB44: 3 | AC44: 4 | AD44: 4 | AE44: 4 | AF44: 3 | AG44: 4 | AH44: 1 | AI44: 2 | AJ44: 1 | AK44: 1 | AL44: Training, stable internet connection | AM44: limited digital tools and skills, unstable internet connection
A45: =A44+1 -> 44 | B45: Secretary | C45: 41-50 | D45: Female | E45: High School Level | F45: 3-5 yrs | G45: Barangay Dayanog Small Coconut Farmers and Fisherfolks Association | H45: 3-5 yrs | I45: 11-20 members | J45: less than 1 ha | K45: Fresh vegetables | L45: No | M45: Trader, Direct selling | N45: Above 20,000 | O45: Yes | P45: Mobile data | Q45: No | S45: 5 | T45: 5 | U45: 4 | V45: 4 | W45: 4 | X45: 5 | Y45: 5 | Z45: 5 | AA45: 5 | AB45: 4 | AC45: 4 | AD45: 4 | AE45: 5 | AF45: 3 | AG45: 4 | AH45: 1 | AI45: 2 | AJ45: 1 | AK45: 1 | AL45: Training, stable internet connection | AM45: limited digital tools and skills, unstable internet connection
A46: =A45+1 -> 45 | B46: President | C46: 41-50 | D46: Male | E46: High School Graduate | F46: 1-2 yrs | G46: PUNDOK MAAMUMAHON | H46: 1-2 yrs | I46: more than 30 | J46: 1-2 ha | K46: Fresh vegetables, Poultry | L46: No | M46: Public market, Trader,Direct selling | N46: Above 20,000 | O46: Yes | P46: Both Mobile & WiFi | Q46: No | S46: 4 | T46: 3 | U46: 3 | V46: 3 | W46: 3 | X46: 4 | Y46: 4 | Z46: 4 | AA46: 4 | AB46: 3 | AC46: 4 | AD46: 3 | AE46: 4 | AF46: 3 | AG46: 4 | AH46: 1 | AI46: 3 | AJ46: 2 | AK46: 1 | AL46: Training | AM46: Limited skills and manpower
A47: =A46+1 -> 46 | B47: Member | C47: 41-50 | D47: Male | E47: College Graduate | F47: 1-2 yrs | G47: PUNDOK MAAMUMAHON | H47: 1-2 yrs | I47: more than 30 | J47: 1-2 ha | K47: Fresh vegetables, Poultry | L47: No | M47: Public market, Trader,Direct selling | N47: Above 20,000 | O47: Yes | P47: Both Mobile & WiFi | Q47: No | S47: 3 | T47: 3 | U47: 3 | V47: 3 | W47: 3 | X47: 4 | Y47: 4 | Z47: 4 | AA47: 4 | AB47: 3 | AC47: 3 | AD47: 3 | AE47: 4 | AF47: 4 | AG47: 4 | AH47: 2 | AI47: 4 | AJ47: 3 | AK47: 2 | AL47: Training | AM47: Limited time and skills for creating content
A48: =A47+1 -> 47 | B48: President | C48: 51 & above | D48: Male | E48: High School Level | F48: 1-2 yrs | G48: Coot-Dinahugan Integrated Farming Association | H48: 1-2 yrs | I48: 21-30 members | J48: less than 1 ha | K48: Livestock | L48: No | M48: Trader, Direct selling | N48: Above 20,000 | O48: Yes | P48: Mobile data | Q48: No | S48: 5 | T48: 5 | U48: 5 | V48: 4 | W48: 4 | X48: 5 | Y48: 4 | Z48: 5 | AA48: 5 | AB48: 3 | AC48: 4 | AD48: 3 | AE48: 4 | AF48: 3 | AG48: 4 | AH48: 1 | AI48: 1 | AJ48: 1 | AK48: 1 | AL48: Training, tools, stable internet connection | AM48: limited tools/ devices and internet access
A49: =A48+1 -> 48 | B49: Secretary | C49: 41-50 | D49: Female | E49: High school Graduate | F49: 1-2 yrs | G49: Coot-Dinahugan Integrated Farming Association | H49: 1-2 yrs | I49: 21-30 members | J49: less than 1 ha | K49: Livestock | L49: No | M49: Trader, Direct selling | N49: Above 20,000 | O49: Yes | P49: Mobile data | Q49: No | S49: 5 | T49: 4 | U49: 4 | V49: 4 | W49: 4 | X49: 5 | Y49: 4 | Z49: 5 | AA49: 4 | AB49: 3 | AC49: 4 | AD49: 3 | AE49: 4 | AF49: 3 | AG49: 3 | AH49: 1 | AI49: 1 | AJ49: 1 | AK49: 1 | AL49: Training, tools, stable internet connection | AM49: limited tools/ devices and internet access
...

Sheet Aggregated
A1: Respondent No. | B1: Role | C1: Age_Range | D1: Sex | E1: Education | F1: Years_Managing | G1: Organization_Name | H1: Years_Established | I1: Membership _Size | J1: Farm_Size | K1: Commodity | L1: Value_Adding/ Processed_ Products_Specify | M1: Market | N1: Income_Level | O1: Has_Device | P1: Internet_ Type | Q1: Attended_Training | R1: Training_Details | S1: TB1 | T1: TB2 | U1: TB3 | V1: TB4 | W1: TB5 | X1: TB6 | Y1: OB7 | Z1: OB8 | AA1: OB9 | AB1: OB10 | AC1: OB11 | AD1: OB12 | AE1: EB13 | AF1: EB14 | AG1: EB15 | AH1: DMA16 | AI1: DMA17 | AJ1: DMA18 | AK1: DMA19 | AL1: Support_ Suggestions | AM1: Challenges
A2: 1 | G2: Sampao Small Water Irrigation System Association, Inc. | S2: =AVERAGE('Raw Data'!S2:S3) -> 4.5 | T2: =AVERAGE('Raw Data'!T2:T3) -> 5 | U2: =AVERAGE('Raw Data'!U2:U3) -> 4 | V2: =AVERAGE('Raw Data'!V2:V3) -> 4 | W2: =AVERAGE('Raw Data'!W2:W3) -> 4 | X2: =AVERAGE('Raw Data'!X2:X3) -> 4 | Y2: =AVERAGE('Raw Data'!Y2:Y3) -> 4.5 | Z2: =AVERAGE('Raw Data'!Z2:Z3) -> 4.5 | ... AK2: =AVERAGE('Raw Data'!AK2:AK3) -> 2.5
A3: =A2+1 -> 2 | G3: Pinangomhan Farmers Association | S3: =AVERAGE('Raw Data'!S4:S5) -> 5 | T3: =AVERAGE('Raw Data'!T4:T5) -> 4.5 | U3: =AVERAGE('Raw Data'!U4:U5) -> 5 | V3: =AVERAGE('Raw Data'!V4:V5) -> 3.5 | W3: =AVERAGE('Raw Data'!W4:W5) -> 3 | X3: =AVERAGE('Raw Data'!X4:X5) -> 4.5 | Y3: =AVERAGE('Raw Data'!Y4:Y5) -> 4 | Z3: =AVERAGE('Raw Data'!Z4:Z5) -> 4.5 | ... AK3: =AVERAGE('Raw Data'!AK4:AK5) -> 2.5
A4: =A3+1 -> 3 | G4: Culaba Integrated Hilltop Farm | S4: =AVERAGE('Raw Data'!S6:S7) -> 3.5 | T4: =AVERAGE('Raw Data'!T6:T7) -> 3.5 | U4: =AVERAGE('Raw Data'!U6:U7) -> 3.5 | V4: =AVERAGE('Raw Data'!V6:V7) -> 3 | W4: =AVERAGE('Raw Data'!W6:W7) -> 3 | X4: =AVERAGE('Raw Data'!X6:X7) -> 3.5 | Y4: =AVERAGE('Raw Data'!Y6:Y7) -> 4 | Z4: =AVERAGE('Raw Data'!Z6:Z7) -> 4 | ... AK4: =AVERAGE('Raw Data'!AK6:AK7) -> 3
A5: =A4+1 -> 4 | G5: Cabucgayan Farmers Association (CAFA) | S5: =AVERAGE('Raw Data'!S8:S9) -> 5 | T5: =AVERAGE('Raw Data'!T8:T9) -> 4.5 | U5: =AVERAGE('Raw Data'!U8:U9) -> 5 | V5: =AVERAGE('Raw Data'!V8:V9) -> 3.5 | W5: =AVERAGE('Raw Data'!W8:W9) -> 4.5 | X5: =AVERAGE('Raw Data'!X8:X9) -> 5 | Y5: =AVERAGE('Raw Data'!Y8:Y9) -> 5 | Z5: =AVERAGE('Raw Data'!Z8:Z9) -> 5 | ... AK5: =AVERAGE('Raw Data'!AK8:AK9) -> 1
A6: =A5+1 -> 5 | G6: Samahan ng mga Manggagawa Para sa Agrikulturang Pangkabuhayan (SMAP) | S6: =AVERAGE('Raw Data'!S10:S11) -> 4.5 | T6: =AVERAGE('Raw Data'!T10:T11) -> 4 | U6: =AVERAGE('Raw Data'!U10:U11) -> 4 | V6: =AVERAGE('Raw Data'!V10:V11) -> 4 | W6: =AVERAGE('Raw Data'!W10:W11) -> 4 | X6: =AVERAGE('Raw Data'!X10:X11) -> 4 | Y6: =AVERAGE('Raw Data'!Y10:Y11) -> 4.5 | Z6: =AVERAGE('Raw Data'!Z10:Z11) -> 4.5 | ... AK6: =AVERAGE('Raw Data'!AK10:AK11) -> 1.5
A7: =A6+1 -> 6 | G7: Tucdao-Anas Farmers’ Irrigator’s Association, Inc. | S7: =AVERAGE('Raw Data'!S12:S13) -> 5 | T7: =AVERAGE('Raw Data'!T12:T13) -> 4.5 | U7: =AVERAGE('Raw Data'!U12:U13) -> 4.5 | V7: =AVERAGE('Raw Data'!V12:V13) -> 3.5 | W7: =AVERAGE('Raw Data'!W12:W13) -> 4 | X7: =AVERAGE('Raw Data'!X12:X13) -> 4 | Y7: =AVERAGE('Raw Data'!Y12:Y13) -> 3.5 | Z7: =AVERAGE('Raw Data'!Z12:Z13) -> 4.5 | ... AK7: =AVERAGE('Raw Data'!AK12:AK13) -> 2
A8: =A7+1 -> 7 | G8: Maripipi Farmers and Fisherfolks Association | S8: =AVERAGE('Raw Data'!S14:S15) -> 4.5 | T8: =AVERAGE('Raw Data'!T14:T15) -> 4 | U8: =AVERAGE('Raw Data'!U14:U15) -> 4 | V8: =AVERAGE('Raw Data'!V14:V15) -> 3 | W8: =AVERAGE('Raw Data'!W14:W15) -> 3.5 | X8: =AVERAGE('Raw Data'!X14:X15) -> 4.5 | Y8: =AVERAGE('Raw Data'!Y14:Y15) -> 4 | Z8: =AVERAGE('Raw Data'!Z14:Z15) -> 5 | ... AK8: =AVERAGE('Raw Data'!AK14:AK15) -> 2.5
A9: =A8+1 -> 8 | G9: Bariis Corn Farmers Association | S9: =AVERAGE('Raw Data'!S16:S17) -> 5 | T9: =AVERAGE('Raw Data'!T16:T17) -> 4 | U9: =AVERAGE('Raw Data'!U16:U17) -> 4.5 | V9: =AVERAGE('Raw Data'!V16:V17) -> 3.5 | W9: =AVERAGE('Raw Data'!W16:W17) -> 3.5 | X9: =AVERAGE('Raw Data'!X16:X17) -> 3.5 | Y9: =AVERAGE('Raw Data'!Y16:Y17) -> 4 | Z9: =AVERAGE('Raw Data'!Z16:Z17) -> 4.5 | ... AK9: =AVERAGE('Raw Data'!AK16:AK17) -> 3
A10: =A9+1 -> 9 | G10: Mga Aktibong Ina sa Brgy. Pinamihagan | S10: =AVERAGE('Raw Data'!S18:S19) -> 5 | T10: =AVERAGE('Raw Data'!T18:T19) -> 5 | U10: =AVERAGE('Raw Data'!U18:U19) -> 5 | V10: =AVERAGE('Raw Data'!V18:V19) -> 4 | W10: =AVERAGE('Raw Data'!W18:W19) -> 4.5 | X10: =AVERAGE('Raw Data'!X18:X19) -> 4 | Y10: =AVERAGE('Raw Data'!Y18:Y19) -> 4.5 | Z10: =AVERAGE('Raw Data'!Z18:Z19) -> 4.5 | ... AK10: =AVERAGE('Raw Data'!AK18:AK19) -> 1
A11: =A10+1 -> 10 | G11: Tamarindo Integrated Peace Development Workers Association (TIPDWA) | S11: =AVERAGE('Raw Data'!S20:S21) -> 4 | T11: =AVERAGE('Raw Data'!T20:T21) -> 3.5 | U11: =AVERAGE('Raw Data'!U20:U21) -> 4 | V11: =AVERAGE('Raw Data'!V20:V21) -> 3.5 | W11: =AVERAGE('Raw Data'!W20:W21) -> 3.5 | X11: =AVERAGE('Raw Data'!X20:X21) -> 3.5 | Y11: =AVERAGE('Raw Data'!Y20:Y21) -> 4 | Z11: =AVERAGE('Raw Data'!Z20:Z21) -> 3.5 | ... AK11: =AVERAGE('Raw Data'!AK20:AK21) -> 1.5
A12: =A11+1 -> 11 | G12: Barangay Aringit Farmers Association | S12: =AVERAGE('Raw Data'!S22:S23) -> 5 | T12: =AVERAGE('Raw Data'!T22:T23) -> 4 | U12: =AVERAGE('Raw Data'!U22:U23) -> 3 | V12: =AVERAGE('Raw Data'!V22:V23) -> 3.5 | W12: =AVERAGE('Raw Data'!W22:W23) -> 3.5 | X12: =AVERAGE('Raw Data'!X22:X23) -> 4 | Y12: =AVERAGE('Raw Data'!Y22:Y23) -> 4.5 | Z12: =AVERAGE('Raw Data'!Z22:Z23) -> 4.5 | ... AK12: =AVERAGE('Raw Data'!AK22:AK23) -> 3
A13: =A12+1 -> 12 | G13: Julitanhon Integrated Farmers Association | S13: =AVERAGE('Raw Data'!S24:S25) -> 3 | T13: =AVERAGE('Raw Data'!T24:T25) -> 4 | U13: =AVERAGE('Raw Data'!U24:U25) -> 3.5 | V13: =AVERAGE('Raw Data'!V24:V25) -> 3 | W13: =AVERAGE('Raw Data'!W24:W25) -> 3.5 | X13: =AVERAGE('Raw Data'!X24:X25) -> 4.5 | Y13: =AVERAGE('Raw Data'!Y24:Y25) -> 4 | Z13: =AVERAGE('Raw Data'!Z24:Z25) -> 4.5 | ... AK13: =AVERAGE('Raw Data'!AK24:AK25) -> 2
A14: =A13+1 -> 13 | G14: Pagburublig han Parag-uma Association | S14: =AVERAGE('Raw Data'!S26:S27) -> 4 | T14: =AVERAGE('Raw Data'!T26:T27) -> 3 | U14: =AVERAGE('Raw Data'!U26:U27) -> 3.5 | V14: =AVERAGE('Raw Data'!V26:V27) -> 3 | W14: =AVERAGE('Raw Data'!W26:W27) -> 3.5 | X14: =AVERAGE('Raw Data'!X26:X27) -> 4 | Y14: =AVERAGE('Raw Data'!Y26:Y27) -> 3 | Z14: =AVERAGE('Raw Data'!Z26:Z27) -> 4 | ... AK14: =AVERAGE('Raw Data'!AK26:AK27) -> 3
A15: =A14+1 -> 14 | G15: Guingauan Small Farmers Association | S15: =AVERAGE('Raw Data'!S28:S29) -> 4.5 | T15: =AVERAGE('Raw Data'!T28:T29) -> 3.5 | U15: =AVERAGE('Raw Data'!U28:U29) -> 4 | V15: =AVERAGE('Raw Data'!V28:V29) -> 3 | W15: =AVERAGE('Raw Data'!W28:W29) -> 3.5 | X15: =AVERAGE('Raw Data'!X28:X29) -> 4 | Y15: =AVERAGE('Raw Data'!Y28:Y29) -> 4.5 | Z15: =AVERAGE('Raw Data'!Z28:Z29) -> 4.5 | ... AK15: =AVERAGE('Raw Data'!AK28:AK29) -> 1.5
A16: =A15+1 -> 15 | G16: Assuncion Del Senior Integrated Farmers Association | S16: =AVERAGE('Raw Data'!S30:S31) -> 5 | T16: =AVERAGE('Raw Data'!T30:T31) -> 5 | U16: =AVERAGE('Raw Data'!U30:U31) -> 5 | V16: =AVERAGE('Raw Data'!V30:V31) -> 4.5 | W16: =AVERAGE('Raw Data'!W30:W31) -> 4.5 | X16: =AVERAGE('Raw Data'!X30:X31) -> 4.5 | Y16: =AVERAGE('Raw Data'!Y30:Y31) -> 5 | Z16: =AVERAGE('Raw Data'!Z30:Z31) -> 5 | ... AK16: =AVERAGE('Raw Data'!AK30:AK31) -> 1.5
A17: =A16+1 -> 16 | G17: San Vicente Farmers and Fisherfolks Association | S17: =AVERAGE('Raw Data'!S32:S33) -> 3.5 | T17: =AVERAGE('Raw Data'!T32:T33) -> 3.5 | U17: =AVERAGE('Raw Data'!U32:U33) -> 3.5 | V17: =AVERAGE('Raw Data'!V32:V33) -> 3 | W17: =AVERAGE('Raw Data'!W32:W33) -> 3 | X17: =AVERAGE('Raw Data'!X32:X33) -> 4 | Y17: =AVERAGE('Raw Data'!Y32:Y33) -> 4.5 | Z17: =AVERAGE('Raw Data'!Z32:Z33) -> 4.5 | ... AK17: =AVERAGE('Raw Data'!AK32:AK33) -> 2.5
A18: =A17+1 -> 17 | G18: Blissful N' Abound Integrated Farmers Association | S18: =AVERAGE('Raw Data'!S34:S35) -> 3.5 | T18: =AVERAGE('Raw Data'!T34:T35) -> 3.5 | U18: =AVERAGE('Raw Data'!U34:U35) -> 3.5 | V18: =AVERAGE('Raw Data'!V34:V35) -> 4.5 | W18: =AVERAGE('Raw Data'!W34:W35) -> 4.5 | X18: =AVERAGE('Raw Data'!X34:X35) -> 4 | Y18: =AVERAGE('Raw Data'!Y34:Y35) -> 5 | Z18: =AVERAGE('Raw Data'!Z34:Z35) -> 5 | ... AK18: =AVERAGE('Raw Data'!AK34:AK35) -> 2
